Workbook

Sheet Summary
A1: BRYT Contract Note - Estimate Summary
A3: Estimate | B3: Sub-Tasks | C3: Required (days) | D3: Optional (days) | E3: Total (days)
A4: Est 1: PDF/Template Management | B4: =COUNTIF('Task Detail'!A:A,A4) -> 43 | C4: =SUMIFS('Task Detail'!E:E,'Task Detail'!A:A,A4,'Task Detail'!F:F,"") -> 9 | D4: =SUMIFS('Task Detail'!E:E,'Task Detail'!A:A,A4,'Task Detail'!F:F,"Yes") -> 4.5 | E4: =C4+D4 -> 13.5
A5: Est 2: DocuSign Integration | B5: =COUNTIF('Task Detail'!A:A,A5) -> 25 | C5: =SUMIFS('Task Detail'!E:E,'Task Detail'!A:A,A5,'Task Detail'!F:F,"") -> 4.125 | D5: =SUMIFS('Task Detail'!E:E,'Task Detail'!A:A,A5,'Task Detail'!F:F,"Yes") -> 3 | E5: =C5+D5 -> 7.125
A6: Est 3a: Training & Enablement | B6: 7 | C6: 4 | D6: 0 | E6: 4
A7: Est 3b: Data Source Extensibility | B7: =COUNTIF('Task Detail'!A:A,A7) -> 26 | C7: =SUMIFS('Task Detail'!E:E,'Task Detail'!A:A,A7,'Task Detail'!F:F,"") -> 6.375 | D7: =SUMIFS('Task Detail'!E:E,'Task Detail'!A:A,A7,'Task Detail'!F:F,"Yes") -> 2.5 | E7: =C7+D7 -> 8.875
A8: Est 4: Bespoke Contracts | B8: =COUNTIF('Task Detail'!A:A,A8) -> 25 | C8: =SUMIFS('Task Detail'!E:E,'Task Detail'!A:A,A8,'Task Detail'!F:F,"") -> 4.75 | D8: =SUMIFS('Task Detail'!E:E,'Task Detail'!A:A,A8,'Task Detail'!F:F,"Yes") -> 3 | E8: =C8+D8 -> 7.75
A9: Est 5: Comparison Audit | B9: =COUNTIF('Task Detail'!A:A,A9) -> 16 | C9: =SUMIFS('Task Detail'!E:E,'Task Detail'!A:A,A9,'Task Detail'!F:F,"") -> 12.375 | D9: =SUMIFS('Task Detail'!E:E,'Task Detail'!A:A,A9,'Task Detail'!F:F,"Yes") -> 0 | E9: =C9+D9 -> 12.375
A10: TOTAL | B10: =SUM(B4:B9) -> 142 | C10: =SUM(C4:C9) -> 40.625 | D10: =SUM(D4:D9) -> 13 | E10: =SUM(E4:E9) -> 53.625

Sheet Task Detail
A1: Estimate | B1: Task ID | C1: Task Description | D1: Category | E1: Days | F1: Optional
A2: Est 1: PDF/Template Management | B2: 1.1 | C2: Define CDK infrastructure for DynamoDB table, S3 buckets, and API Gateway routes | D2: infrastructure | E2: 1
A3: Est 1: PDF/Template Management | B3: 1.2 | C3: Create shared TypeScript interfaces and types | D3: api_backend | E3: 0.125
A4: Est 1: PDF/Template Management | B4: 1.3 | C4: Implement specification tree validation utility | D4: api_backend | E4: 0.125
A5: Est 1: PDF/Template Management | B5: 1.4 | C5: Write property tests for specification tree validation | D5: testing | E5: 0.5 | F5: Yes
A6: Est 1: PDF/Template Management | B6: 2.1 | C6: Implement `list-templates` handler | D6: api_backend | E6: 0.125
A7: Est 1: PDF/Template Management | B7: 2.2 | C7: Implement `create-template` handler | D7: api_backend | E7: 0.125
A8: Est 1: PDF/Template Management | B8: 2.3 | C8: Implement `get-template` handler | D8: api_backend | E8: 0.125
A9: Est 1: PDF/Template Management | B9: 2.4 | C9: Implement `update-template` handler | D9: api_backend | E9: 0.125
A10: Est 1: PDF/Template Management | B10: 2.5 | C10: Implement `delete-template` handler | D10: api_backend | E10: 0.125
A11: Est 1: PDF/Template Management | B11: 2.6 | C11: Implement `reorder-templates` handler | D11: api_backend | E11: 0.125
A12: Est 1: PDF/Template Management | B12: 2.7 | C12: Write property tests for template API logic | D12: testing | E12: 0.5 | F12: Yes
A13: Est 1: PDF/Template Management | B13: 3.1 | C13: Implement `list-sections` handler | D13: api_backend | E13: 0.125
A14: Est 1: PDF/Template Management | B14: 3.2 | C14: Implement `add-section` handler | D14: api_backend | E14: 0.125
A15: Est 1: PDF/Template Management | B15: 3.3 | C15: Implement `remove-section` handler | D15: api_backend | E15: 0.125
A16: Est 1: PDF/Template Management | B16: 3.4 | C16: Implement `reorder-sections` handler | D16: api_backend | E16: 0.125
A17: Est 1: PDF/Template Management | B17: 3.5 | C17: Implement `get-section-schema` and `save-section-schema` handlers | D17: api_backend | E17: 0.125
A18: Est 1: PDF/Template Management | B18: 3.6 | C18: Implement section version history handlers | D18: api_backend | E18: 0.125
A19: Est 1: PDF/Template Management | B19: 3.7 | C19: Implement shared section CRUD handlers | D19: api_backend | E19: 0.125
A20: Est 1: PDF/Template Management | B20: 3.8 | C20: Implement template change log | D20: api_backend | E20: 0.125
A21: Est 1: PDF/Template Management | B21: 3.9 | C21: Write property tests for section API logic | D21: testing | E21: 0.5 | F21: Yes
A22: Est 1: PDF/Template Management | B22: 4.1 | C22: Implement `get-rule` handler | D22: api_backend | E22: 0.125
A23: Est 1: PDF/Template Management | B23: 4.2 | C23: Implement `save-rule` handler | D23: api_backend | E23: 0.125
A24: Est 1: PDF/Template Management | B24: 6.1 | C24: Implement specification evaluator | D24: api_backend | E24: 0.125
A25: Est 1: PDF/Template Management | B25: 6.2 | C25: Write property tests for specification evaluator | D25: testing | E25: 0.5 | F25: Yes
A26: Est 1: PDF/Template Management | B26: 6.3 | C26: Implement template selection logic | D26: api_backend | E26: 0.125
A27: Est 1: PDF/Template Management | B27: 6.4 | C27: Implement section renderer | D27: api_backend | E27: 0.125
A28: Est 1: PDF/Template Management | B28: 6.5 | C28: Write property test for section rendering | D28: testing | E28: 0.5 | F28: Yes
A29: Est 1: PDF/Template Management | B29: 6.6 | C29: Implement PDF stitcher | D29: api_backend | E29: 0.125
A30: Est 1: PDF/Template Management | B30: 6.7 | C30: Write property test for PDF stitching | D30: testing | E30: 0.5 | F30: Yes
A31: Est 1: PDF/Template Management | B31: 6.8 | C31: Implement XML-to-JSON parser and S3 trigger handler | D31: api_backend | E31: 0.125
A32: Est 1: PDF/Template Management | B32: 6.9 | C32: Write property tests for pipeline | D32: testing | E32: 0.5 | F32: Yes
A33: Est 1: PDF/Template Management | B33: 8.1 | C33: Create ContractNoteModule with routing | D33: frontend | E33: 0.5
A34: Est 1: PDF/Template Management | B34: 8.2 | C34: Implement TemplateService, SectionService, and RulesService | D34: frontend | E34: 0.5
A35: Est 1: PDF/Template Management | B35: 9.1 | C35: Implement TemplateListComponent | D35: frontend | E35: 0.5
A36: Est 1: PDF/Template Management | B36: 9.2 | C36: Implement TemplateEditComponent | D36: frontend | E36: 0.5
A37: Est 1: PDF/Template Management | B37: 9.2a | C37: Implement SectionVersionHistoryComponent | D37: frontend | E37: 0.5
A38: Est 1: PDF/Template Management | B38: 9.3 | C38: Implement RulesConfigComponent | D38: frontend | E38: 0.5
A39: Est 1: PDF/Template Management | B39: 9.4 | C39: Implement SectionEditorComponent (Web Component wrapper for pdf-me Designer) | D39: frontend | E39: 0.5
A40: Est 1: PDF/Template Management | B40: 9.5 | C40: Implement SharedSectionsComponent and SharedSectionDetailComponent | D40: frontend | E40: 0.5
...
